####################
Mon Mar 19 13:31:15 EDT 2018
Failed to import the site module
Traceback (most recent call last):
  File "/Library/Frameworks/Python.framework/Versions/3.5/lib/python3.5/site.py", line 247, in getuserbase
    USER_BASE = get_config_var('userbase')
  File "/Library/Frameworks/Python.framework/Versions/3.5/lib/python3.5/_osx_support.py", line 4, in <module>
    import re
  File "/Library/Frameworks/Python.framework/Versions/3.5/lib/python3.5/re.py", line 335, in <module>
    import copyreg
  File "/Library/Python/2.7/site-packages/copyreg/__init__.py", line 7, in <module>
    raise ImportError('This package should not be accessible on Python 3. '
ImportError: This package should not be accessible on Python 3. Either you are trying to run from the python-future src folder or your installation of python-future is corrupted.
####################
Mon Mar 19 13:31:15 EDT 2018
Failed to import the site module
Traceback (most recent call last):
  File "/Library/Frameworks/Python.framework/Versions/3.5/lib/python3.5/site.py", line 247, in getuserbase
    USER_BASE = get_config_var('userbase')
  File "/Library/Frameworks/Python.framework/Versions/3.5/lib/python3.5/_osx_support.py", line 4, in <module>
    import re
  File "/Library/Frameworks/Python.framework/Versions/3.5/lib/python3.5/re.py", line 335, in <module>
    import copyreg
  File "/Library/Python/2.7/site-packages/copyreg/__init__.py", line 7, in <module>
    raise ImportError('This package should not be accessible on Python 3. '
ImportError: This package should not be accessible on Python 3. Either you are trying to run from the python-future src folder or your installation of python-future is corrupted.
